2022-05-11 11:19:45,616 INFO    MainThread:20404 [internal.py:wandb_internal():92] W&B internal server running at pid: 20404, started at: 2022-05-11 11:19:45.615622
2022-05-11 11:19:45,620 INFO    WriterThread:20404 [datastore.py:open_for_write():77] open: C:\Users\gizem\Documents\GitHub\noisy_fair\wandb\run-20220511_111943-2hd7jqpc\run-2hd7jqpc.wandb
2022-05-11 11:19:45,627 DEBUG   SenderThread:20404 [sender.py:send():235] send: header
2022-05-11 11:19:45,627 DEBUG   SenderThread:20404 [sender.py:send():235] send: run
2022-05-11 11:20:13,511 DEBUG   HandlerThread:20404 [handler.py:handle_request():141] handle_request: shutdown
2022-05-11 11:20:13,512 INFO    HandlerThread:20404 [handler.py:finish():790] shutting down handler
2022-05-11 11:20:13,792 INFO    WriterThread:20404 [datastore.py:close():281] close: C:\Users\gizem\Documents\GitHub\noisy_fair\wandb\run-20220511_111943-2hd7jqpc\run-2hd7jqpc.wandb
2022-05-11 11:20:20,966 ERROR   SenderThread:20404 [retry.py:__call__():126] Retry attempt failed:
Traceback (most recent call last):
  File "C:\Users\gizem\anaconda3\envs\iw\lib\site-packages\urllib3\connectionpool.py", line 449, in _make_request
    six.raise_from(e, None)
  File "<string>", line 3, in raise_from
  File "C:\Users\gizem\anaconda3\envs\iw\lib\site-packages\urllib3\connectionpool.py", line 444, in _make_request
    httplib_response = conn.getresponse()
  File "C:\Users\gizem\anaconda3\envs\iw\lib\http\client.py", line 1374, in getresponse
    response.begin()
  File "C:\Users\gizem\anaconda3\envs\iw\lib\http\client.py", line 318, in begin
    version, status, reason = self._read_status()
  File "C:\Users\gizem\anaconda3\envs\iw\lib\http\client.py", line 279, in _read_status
    line = str(self.fp.readline(_MAXLINE + 1), "iso-8859-1")
  File "C:\Users\gizem\anaconda3\envs\iw\lib\socket.py", line 705, in readinto
    return self._sock.recv_into(b)
  File "C:\Users\gizem\anaconda3\envs\iw\lib\ssl.py", line 1273, in recv_into
    return self.read(nbytes, buffer)
  File "C:\Users\gizem\anaconda3\envs\iw\lib\ssl.py", line 1129, in read
    return self._sslobj.read(len, buffer)
TimeoutError: The read operation timed out

During handling of the above exception, another exception occurred:

Traceback (most recent call last):
  File "C:\Users\gizem\anaconda3\envs\iw\lib\site-packages\requests\adapters.py", line 440, in send
    resp = conn.urlopen(
  File "C:\Users\gizem\anaconda3\envs\iw\lib\site-packages\urllib3\connectionpool.py", line 785, in urlopen
    retries = retries.increment(
  File "C:\Users\gizem\anaconda3\envs\iw\lib\site-packages\urllib3\util\retry.py", line 550, in increment
    raise six.reraise(type(error), error, _stacktrace)
  File "C:\Users\gizem\anaconda3\envs\iw\lib\site-packages\urllib3\packages\six.py", line 770, in reraise
    raise value
  File "C:\Users\gizem\anaconda3\envs\iw\lib\site-packages\urllib3\connectionpool.py", line 703, in urlopen
    httplib_response = self._make_request(
  File "C:\Users\gizem\anaconda3\envs\iw\lib\site-packages\urllib3\connectionpool.py", line 451, in _make_request
    self._raise_timeout(err=e, url=url, timeout_value=read_timeout)
  File "C:\Users\gizem\anaconda3\envs\iw\lib\site-packages\urllib3\connectionpool.py", line 340, in _raise_timeout
    raise ReadTimeoutError(
urllib3.exceptions.ReadTimeoutError: HTTPSConnectionPool(host='api.wandb.ai', port=443): Read timed out. (read timeout=10)

During handling of the above exception, another exception occurred:

Traceback (most recent call last):
  File "C:\Users\gizem\anaconda3\envs\iw\lib\site-packages\wandb\sdk\lib\retry.py", line 102, in __call__
    result = self._call_fn(*args, **kwargs)
  File "C:\Users\gizem\anaconda3\envs\iw\lib\site-packages\wandb\sdk\internal\internal_api.py", line 141, in execute
    return self.client.execute(*args, **kwargs)
  File "C:\Users\gizem\anaconda3\envs\iw\lib\site-packages\wandb\vendor\gql-0.2.0\wandb_gql\client.py", line 52, in execute
    result = self._get_result(document, *args, **kwargs)
  File "C:\Users\gizem\anaconda3\envs\iw\lib\site-packages\wandb\vendor\gql-0.2.0\wandb_gql\client.py", line 60, in _get_result
    return self.transport.execute(document, *args, **kwargs)
  File "C:\Users\gizem\anaconda3\envs\iw\lib\site-packages\wandb\vendor\gql-0.2.0\wandb_gql\transport\requests.py", line 38, in execute
    request = requests.post(self.url, **post_args)
  File "C:\Users\gizem\anaconda3\envs\iw\lib\site-packages\requests\api.py", line 117, in post
    return request('post', url, data=data, json=json, **kwargs)
  File "C:\Users\gizem\anaconda3\envs\iw\lib\site-packages\requests\api.py", line 61, in request
    return session.request(method=method, url=url, **kwargs)
  File "C:\Users\gizem\anaconda3\envs\iw\lib\site-packages\requests\sessions.py", line 529, in request
    resp = self.send(prep, **send_kwargs)
  File "C:\Users\gizem\anaconda3\envs\iw\lib\site-packages\requests\sessions.py", line 645, in send
    r = adapter.send(request, **kwargs)
  File "C:\Users\gizem\anaconda3\envs\iw\lib\site-packages\requests\adapters.py", line 532, in send
    raise ReadTimeout(e, request=request)
requests.exceptions.ReadTimeout: HTTPSConnectionPool(host='api.wandb.ai', port=443): Read timed out. (read timeout=10)
2022-05-11 11:20:51,602 INFO    SenderThread:20404 [dir_watcher.py:__init__():169] watching files in: C:\Users\gizem\Documents\GitHub\noisy_fair\wandb\run-20220511_111943-2hd7jqpc\files
2022-05-11 11:20:51,602 INFO    SenderThread:20404 [sender.py:_start_run_threads():812] run started: 2hd7jqpc with start time 1652260783
2022-05-11 11:20:51,602 INFO    SenderThread:20404 [sender.py:finish():1107] shutting down sender
2022-05-11 11:20:51,602 INFO    SenderThread:20404 [dir_watcher.py:finish():283] shutting down directory watcher
2022-05-11 11:20:52,617 INFO    SenderThread:20404 [dir_watcher.py:finish():313] scan: C:\Users\gizem\Documents\GitHub\noisy_fair\wandb\run-20220511_111943-2hd7jqpc\files
2022-05-11 11:20:52,617 INFO    SenderThread:20404 [dir_watcher.py:finish():327] scan save: C:\Users\gizem\Documents\GitHub\noisy_fair\wandb\run-20220511_111943-2hd7jqpc\files\config.yaml config.yaml
2022-05-11 11:20:52,617 INFO    SenderThread:20404 [file_pusher.py:finish():145] shutting down file pusher
2022-05-11 11:20:52,617 INFO    SenderThread:20404 [file_pusher.py:join():150] waiting for file pusher
2022-05-11 11:21:14,507 INFO    Thread-13 :20404 [upload_job.py:push():137] Uploaded file C:\Users\gizem\Documents\GitHub\noisy_fair\wandb\run-20220511_111943-2hd7jqpc\files\config.yaml
2022-05-11 11:21:22,987 INFO    MainThread:20404 [internal.py:handle_exit():82] Internal process exited
