2022-05-11 11:19:43,212 INFO    MainThread:9904 [wandb_setup.py:_flush():75] Loading settings from C:\Users\gizem\.config\wandb\settings
2022-05-11 11:19:43,212 INFO    MainThread:9904 [wandb_setup.py:_flush():75] Loading settings from C:\Users\gizem\Documents\GitHub\noisy_fair\wandb\settings
2022-05-11 11:19:43,212 INFO    MainThread:9904 [wandb_setup.py:_flush():75] Loading settings from environment variables: {}
2022-05-11 11:19:43,212 INFO    MainThread:9904 [wandb_setup.py:_flush():75] Inferring run settings from compute environment: {'program_relpath': 'analytical.py', 'program': 'c:\\Users\\gizem\\Documents\\GitHub\\noisy_fair\\analytical.py'}
2022-05-11 11:19:43,213 INFO    MainThread:9904 [wandb_init.py:_log_setup():438] Logging user logs to C:\Users\gizem\Documents\GitHub\noisy_fair\wandb\run-20220511_111943-2hd7jqpc\logs\debug.log
2022-05-11 11:19:43,217 INFO    MainThread:9904 [wandb_init.py:_log_setup():439] Logging internal logs to C:\Users\gizem\Documents\GitHub\noisy_fair\wandb\run-20220511_111943-2hd7jqpc\logs\debug-internal.log
2022-05-11 11:19:43,218 INFO    MainThread:9904 [wandb_init.py:init():472] calling init triggers
2022-05-11 11:19:43,218 INFO    MainThread:9904 [wandb_init.py:init():475] wandb.init called with sweep_config: {}
config: {'n_train': 100, 'n_test': 10000.0, 'n_features': 19, 'tau': 1.0, 'SNR': 10, 'n_informative': 19, 'n_redundant': 0, 'n_repeated': 0, 'n_useless': 0, 'n_clusters_per_class': 1, 'class_sep': 3.1622776601683795, 's': 1, 'label_noise_prob': 0}
2022-05-11 11:19:43,219 INFO    MainThread:9904 [wandb_init.py:init():525] starting backend
2022-05-11 11:19:43,219 INFO    MainThread:9904 [backend.py:_multiprocessing_setup():99] multiprocessing start_methods=spawn, using: spawn
2022-05-11 11:19:43,233 INFO    MainThread:9904 [backend.py:ensure_launched():219] starting backend process...
2022-05-11 11:19:43,412 INFO    MainThread:9904 [backend.py:ensure_launched():224] started backend process with pid: 20404
2022-05-11 11:19:43,412 INFO    MainThread:9904 [wandb_init.py:init():534] backend started and connected
2022-05-11 11:19:43,430 INFO    MainThread:9904 [wandb_init.py:init():598] updated telemetry
2022-05-11 11:19:43,501 INFO    MainThread:9904 [wandb_init.py:init():629] communicating run to backend with 30 second timeout
2022-05-11 11:20:13,510 INFO    MainThread:9904 [interface_shared.py:_communicate_run():325] couldn't get run from backend
2022-05-11 11:20:13,510 ERROR   MainThread:9904 [wandb_init.py:init():634] backend process timed out
2022-05-11 11:20:13,511 ERROR   MainThread:9904 [wandb_init.py:init():645] encountered error: Error communicating with wandb process
try: wandb.init(settings=wandb.Settings(start_method='fork'))
or:  wandb.init(settings=wandb.Settings(start_method='thread'))
For more info see: https://docs.wandb.ai/library/init#init-start-error
2022-05-11 11:20:32,491 ERROR   Thread-7 (wrapped_target):9904 [retry.py:__call__():126] Retry attempt failed:
Traceback (most recent call last):
  File "C:\Users\gizem\anaconda3\envs\iw\lib\site-packages\urllib3\connectionpool.py", line 449, in _make_request
    six.raise_from(e, None)
  File "<string>", line 3, in raise_from
  File "C:\Users\gizem\anaconda3\envs\iw\lib\site-packages\urllib3\connectionpool.py", line 444, in _make_request
    httplib_response = conn.getresponse()
  File "C:\Users\gizem\anaconda3\envs\iw\lib\http\client.py", line 1374, in getresponse
    response.begin()
  File "C:\Users\gizem\anaconda3\envs\iw\lib\http\client.py", line 318, in begin
    version, status, reason = self._read_status()
  File "C:\Users\gizem\anaconda3\envs\iw\lib\http\client.py", line 279, in _read_status
    line = str(self.fp.readline(_MAXLINE + 1), "iso-8859-1")
  File "C:\Users\gizem\anaconda3\envs\iw\lib\socket.py", line 705, in readinto
    return self._sock.recv_into(b)
  File "C:\Users\gizem\anaconda3\envs\iw\lib\ssl.py", line 1273, in recv_into
    return self.read(nbytes, buffer)
  File "C:\Users\gizem\anaconda3\envs\iw\lib\ssl.py", line 1129, in read
    return self._sslobj.read(len, buffer)
TimeoutError: The read operation timed out

During handling of the above exception, another exception occurred:

Traceback (most recent call last):
  File "C:\Users\gizem\anaconda3\envs\iw\lib\site-packages\requests\adapters.py", line 440, in send
    resp = conn.urlopen(
  File "C:\Users\gizem\anaconda3\envs\iw\lib\site-packages\urllib3\connectionpool.py", line 785, in urlopen
    retries = retries.increment(
  File "C:\Users\gizem\anaconda3\envs\iw\lib\site-packages\urllib3\util\retry.py", line 550, in increment
    raise six.reraise(type(error), error, _stacktrace)
  File "C:\Users\gizem\anaconda3\envs\iw\lib\site-packages\urllib3\packages\six.py", line 770, in reraise
    raise value
  File "C:\Users\gizem\anaconda3\envs\iw\lib\site-packages\urllib3\connectionpool.py", line 703, in urlopen
    httplib_response = self._make_request(
  File "C:\Users\gizem\anaconda3\envs\iw\lib\site-packages\urllib3\connectionpool.py", line 451, in _make_request
    self._raise_timeout(err=e, url=url, timeout_value=read_timeout)
  File "C:\Users\gizem\anaconda3\envs\iw\lib\site-packages\urllib3\connectionpool.py", line 340, in _raise_timeout
    raise ReadTimeoutError(
urllib3.exceptions.ReadTimeoutError: HTTPSConnectionPool(host='api.wandb.ai', port=443): Read timed out. (read timeout=10)

During handling of the above exception, another exception occurred:

Traceback (most recent call last):
  File "C:\Users\gizem\anaconda3\envs\iw\lib\site-packages\wandb\sdk\lib\retry.py", line 102, in __call__
    result = self._call_fn(*args, **kwargs)
  File "C:\Users\gizem\anaconda3\envs\iw\lib\site-packages\wandb\sdk\internal\internal_api.py", line 141, in execute
    return self.client.execute(*args, **kwargs)
  File "C:\Users\gizem\anaconda3\envs\iw\lib\site-packages\wandb\vendor\gql-0.2.0\wandb_gql\client.py", line 52, in execute
    result = self._get_result(document, *args, **kwargs)
  File "C:\Users\gizem\anaconda3\envs\iw\lib\site-packages\wandb\vendor\gql-0.2.0\wandb_gql\client.py", line 60, in _get_result
    return self.transport.execute(document, *args, **kwargs)
  File "C:\Users\gizem\anaconda3\envs\iw\lib\site-packages\wandb\vendor\gql-0.2.0\wandb_gql\transport\requests.py", line 38, in execute
    request = requests.post(self.url, **post_args)
  File "C:\Users\gizem\anaconda3\envs\iw\lib\site-packages\requests\api.py", line 117, in post
    return request('post', url, data=data, json=json, **kwargs)
  File "C:\Users\gizem\anaconda3\envs\iw\lib\site-packages\requests\api.py", line 61, in request
    return session.request(method=method, url=url, **kwargs)
  File "C:\Users\gizem\anaconda3\envs\iw\lib\site-packages\requests\sessions.py", line 529, in request
    resp = self.send(prep, **send_kwargs)
  File "C:\Users\gizem\anaconda3\envs\iw\lib\site-packages\requests\sessions.py", line 645, in send
    r = adapter.send(request, **kwargs)
  File "C:\Users\gizem\anaconda3\envs\iw\lib\site-packages\requests\adapters.py", line 532, in send
    raise ReadTimeout(e, request=request)
requests.exceptions.ReadTimeout: HTTPSConnectionPool(host='api.wandb.ai', port=443): Read timed out. (read timeout=10)
2022-05-11 11:21:23,154 INFO    MainThread:9904 [wandb_init.py:teardown():286] tearing down wandb.init
