2022-05-27 15:00:58,291 INFO    MainThread:16956 [internal.py:wandb_internal():92] W&B internal server running at pid: 16956, started at: 2022-05-27 15:00:58.275711
2022-05-27 15:00:58,295 INFO    WriterThread:16956 [datastore.py:open_for_write():77] open: C:\Users\gizem\Documents\GitHub\noisy_fair\wandb\run-20220527_150054-2f8cby72\run-2f8cby72.wandb
2022-05-27 15:00:58,301 DEBUG   SenderThread:16956 [sender.py:send():235] send: header
2022-05-27 15:00:58,301 DEBUG   SenderThread:16956 [sender.py:send():235] send: run
2022-05-27 15:00:59,042 DEBUG   HandlerThread:16956 [handler.py:handle_request():141] handle_request: check_version
2022-05-27 15:00:59,049 INFO    SenderThread:16956 [dir_watcher.py:__init__():169] watching files in: C:\Users\gizem\Documents\GitHub\noisy_fair\wandb\run-20220527_150054-2f8cby72\files
2022-05-27 15:00:59,050 INFO    SenderThread:16956 [sender.py:_start_run_threads():812] run started: 2f8cby72 with start time 1653656455
2022-05-27 15:00:59,050 DEBUG   SenderThread:16956 [sender.py:send():235] send: summary
2022-05-27 15:00:59,051 INFO    SenderThread:16956 [sender.py:_save_file():947] saving file wandb-summary.json with policy end
2022-05-27 15:00:59,051 DEBUG   SenderThread:16956 [sender.py:send_request():249] send_request: check_version
2022-05-27 15:00:59,688 DEBUG   HandlerThread:16956 [handler.py:handle_request():141] handle_request: run_start
2022-05-27 15:01:00,067 INFO    Thread-11 :16956 [dir_watcher.py:_on_file_created():217] file/dir created: C:\Users\gizem\Documents\GitHub\noisy_fair\wandb\run-20220527_150054-2f8cby72\files\wandb-summary.json
2022-05-27 15:01:00,815 DEBUG   HandlerThread:16956 [meta.py:__init__():37] meta init
2022-05-27 15:01:00,815 DEBUG   HandlerThread:16956 [meta.py:__init__():51] meta init done
2022-05-27 15:01:00,815 DEBUG   HandlerThread:16956 [meta.py:probe():211] probe
2022-05-27 15:01:00,931 DEBUG   HandlerThread:16956 [meta.py:_setup_git():201] setup git
2022-05-27 15:01:01,057 DEBUG   HandlerThread:16956 [meta.py:_setup_git():208] setup git done
2022-05-27 15:01:01,058 DEBUG   HandlerThread:16956 [meta.py:_save_pip():55] save pip
2022-05-27 15:01:01,058 DEBUG   HandlerThread:16956 [meta.py:_save_pip():69] save pip done
2022-05-27 15:01:01,058 DEBUG   HandlerThread:16956 [meta.py:_save_conda():76] save conda
2022-05-27 15:01:01,076 INFO    Thread-11 :16956 [dir_watcher.py:_on_file_created():217] file/dir created: C:\Users\gizem\Documents\GitHub\noisy_fair\wandb\run-20220527_150054-2f8cby72\files\conda-environment.yaml
2022-05-27 15:01:01,077 INFO    Thread-11 :16956 [dir_watcher.py:_on_file_created():217] file/dir created: C:\Users\gizem\Documents\GitHub\noisy_fair\wandb\run-20220527_150054-2f8cby72\files\requirements.txt
2022-05-27 15:01:01,079 ERROR   HandlerThread:16956 [meta.py:_save_conda():85] Error saving conda packages
Traceback (most recent call last):
  File "C:\Users\gizem\anaconda3\envs\soccer2\lib\site-packages\wandb\sdk\internal\meta.py", line 81, in _save_conda
    subprocess.call(
  File "C:\Users\gizem\anaconda3\envs\soccer2\lib\subprocess.py", line 345, in call
    with Popen(*popenargs, **kwargs) as p:
  File "C:\Users\gizem\anaconda3\envs\soccer2\lib\subprocess.py", line 966, in __init__
    self._execute_child(args, executable, preexec_fn, close_fds,
  File "C:\Users\gizem\anaconda3\envs\soccer2\lib\subprocess.py", line 1435, in _execute_child
    hp, ht, pid, tid = _winapi.CreateProcess(executable, args,
FileNotFoundError: [WinError 2] The system cannot find the file specified
2022-05-27 15:01:01,082 DEBUG   HandlerThread:16956 [meta.py:_save_conda():86] save conda done
2022-05-27 15:01:01,082 DEBUG   HandlerThread:16956 [meta.py:probe():249] probe done
2022-05-27 15:01:01,391 DEBUG   SenderThread:16956 [sender.py:send():235] send: files
2022-05-27 15:01:01,392 INFO    SenderThread:16956 [sender.py:_save_file():947] saving file wandb-metadata.json with policy now
2022-05-27 15:01:01,392 DEBUG   HandlerThread:16956 [handler.py:handle_request():141] handle_request: stop_status
2022-05-27 15:01:01,394 DEBUG   SenderThread:16956 [sender.py:send_request():249] send_request: stop_status
2022-05-27 15:01:02,089 INFO    Thread-11 :16956 [dir_watcher.py:_on_file_created():217] file/dir created: C:\Users\gizem\Documents\GitHub\noisy_fair\wandb\run-20220527_150054-2f8cby72\files\wandb-metadata.json
2022-05-27 15:01:02,090 INFO    Thread-11 :16956 [dir_watcher.py:_on_file_created():217] file/dir created: C:\Users\gizem\Documents\GitHub\noisy_fair\wandb\run-20220527_150054-2f8cby72\files\output.log
2022-05-27 15:01:02,634 DEBUG   SenderThread:16956 [sender.py:send():235] send: telemetry
2022-05-27 15:01:03,846 INFO    Thread-17 :16956 [upload_job.py:push():137] Uploaded file C:\Users\gizem\AppData\Local\Temp\tmpnv51_zm2wandb\37beako5-wandb-metadata.json
2022-05-27 15:01:20,539 DEBUG   HandlerThread:16956 [handler.py:handle_request():141] handle_request: stop_status
2022-05-27 15:01:20,539 DEBUG   SenderThread:16956 [sender.py:send_request():249] send_request: stop_status
2022-05-27 15:01:30,343 INFO    Thread-11 :16956 [dir_watcher.py:_on_file_modified():230] file/dir modified: C:\Users\gizem\Documents\GitHub\noisy_fair\wandb\run-20220527_150054-2f8cby72\files\config.yaml
2022-05-27 15:01:34,399 INFO    Thread-11 :16956 [dir_watcher.py:_on_file_modified():230] file/dir modified: C:\Users\gizem\Documents\GitHub\noisy_fair\wandb\run-20220527_150054-2f8cby72\files\output.log
2022-05-27 15:01:36,390 DEBUG   HandlerThread:16956 [handler.py:handle_request():141] handle_request: stop_status
2022-05-27 15:01:36,390 DEBUG   SenderThread:16956 [sender.py:send_request():249] send_request: stop_status
2022-05-27 15:01:37,510 DEBUG   SenderThread:16956 [sender.py:send():235] send: stats
2022-05-27 15:01:52,338 DEBUG   HandlerThread:16956 [handler.py:handle_request():141] handle_request: stop_status
2022-05-27 15:01:52,339 DEBUG   SenderThread:16956 [sender.py:send_request():249] send_request: stop_status
2022-05-27 15:01:59,050 DEBUG   HandlerThread:16956 [handler.py:handle_request():141] handle_request: partial_history
2022-05-27 15:01:59,053 DEBUG   SenderThread:16956 [sender.py:send():235] send: history
2022-05-27 15:01:59,053 DEBUG   SenderThread:16956 [sender.py:send():235] send: summary
2022-05-27 15:01:59,059 INFO    SenderThread:16956 [sender.py:_save_file():947] saving file wandb-summary.json with policy end
2022-05-27 15:01:59,616 INFO    Thread-11 :16956 [dir_watcher.py:_on_file_modified():230] file/dir modified: C:\Users\gizem\Documents\GitHub\noisy_fair\wandb\run-20220527_150054-2f8cby72\files\wandb-summary.json
2022-05-27 15:02:03,658 INFO    Thread-11 :16956 [dir_watcher.py:_on_file_modified():230] file/dir modified: C:\Users\gizem\Documents\GitHub\noisy_fair\wandb\run-20220527_150054-2f8cby72\files\output.log
2022-05-27 15:02:05,675 INFO    Thread-11 :16956 [dir_watcher.py:_on_file_modified():230] file/dir modified: C:\Users\gizem\Documents\GitHub\noisy_fair\wandb\run-20220527_150054-2f8cby72\files\output.log
2022-05-27 15:02:08,230 DEBUG   HandlerThread:16956 [handler.py:handle_request():141] handle_request: stop_status
2022-05-27 15:02:08,231 DEBUG   SenderThread:16956 [sender.py:send_request():249] send_request: stop_status
2022-05-27 15:02:16,855 DEBUG   SenderThread:16956 [sender.py:send():235] send: stats
2022-05-27 15:02:23,968 DEBUG   HandlerThread:16956 [handler.py:handle_request():141] handle_request: stop_status
2022-05-27 15:02:23,969 DEBUG   SenderThread:16956 [sender.py:send_request():249] send_request: stop_status
2022-05-27 16:03:45,133 WARNING FileStreamThread:16956 [file_stream.py:request_with_retry():594] requests_with_retry encountered retryable exception: ('Connection aborted.', RemoteDisconnected('Remote end closed connection without response')). func: <bound method Session.post of <requests.sessions.Session object at 0x00000159EBA56170>>, args: ('https://api.wandb.ai/files/sml-eth/noisy-fair/2f8cby72/file_stream',), kwargs: {'json': {'files': {'wandb-events.jsonl': {'offset': 1, 'content': ['{"system.gpu.0.gpu": 0.0, "system.gpu.0.memory": 0.0, "system.gpu.0.memoryAllocated": 3.22, "system.gpu.0.temp": 49.0, "system.cpu": 25.51, "system.memory": 81.24, "system.disk": 84.7, "system.proc.memory.availableMB": 3043.74, "system.proc.memory.rssMB": 96.29, "system.proc.memory.percent": 0.59, "system.proc.cpu.threads": 16.2, "system.network.sent": 82109, "system.network.recv": 338502, "_wandb": true, "_timestamp": 1653656536, "_runtime": 81}']}}, 'dropped': 0}}
2022-05-27 16:03:47,323 WARNING FileStreamThread:16956 [file_stream.py:request_with_retry():594] requests_with_retry encountered retryable exception: HTTPSConnectionPool(host='api.wandb.ai', port=443): Max retries exceeded with url: /files/sml-eth/noisy-fair/2f8cby72/file_stream (Caused by NewConnectionError('<urllib3.connection.HTTPSConnection object at 0x00000159EBCBE9B0>: Failed to establish a new connection: [Errno 11001] getaddrinfo failed')). func: <bound method Session.post of <requests.sessions.Session object at 0x00000159EBA56170>>, args: ('https://api.wandb.ai/files/sml-eth/noisy-fair/2f8cby72/file_stream',), kwargs: {'json': {'files': {'wandb-events.jsonl': {'offset': 1, 'content': ['{"system.gpu.0.gpu": 0.0, "system.gpu.0.memory": 0.0, "system.gpu.0.memoryAllocated": 3.22, "system.gpu.0.temp": 49.0, "system.cpu": 25.51, "system.memory": 81.24, "system.disk": 84.7, "system.proc.memory.availableMB": 3043.74, "system.proc.memory.rssMB": 96.29, "system.proc.memory.percent": 0.59, "system.proc.cpu.threads": 16.2, "system.network.sent": 82109, "system.network.recv": 338502, "_wandb": true, "_timestamp": 1653656536, "_runtime": 81}']}}, 'dropped': 0}}
2022-05-27 16:03:48,404 ERROR   SenderThread:16956 [retry.py:__call__():126] Retry attempt failed:
Traceback (most recent call last):
  File "C:\Users\gizem\anaconda3\envs\soccer2\lib\site-packages\urllib3\connection.py", line 174, in _new_conn
    conn = connection.create_connection(
  File "C:\Users\gizem\anaconda3\envs\soccer2\lib\site-packages\urllib3\util\connection.py", line 72, in create_connection
    for res in socket.getaddrinfo(host, port, family, socket.SOCK_STREAM):
  File "C:\Users\gizem\anaconda3\envs\soccer2\lib\socket.py", line 955, in getaddrinfo
    for res in _socket.getaddrinfo(host, port, family, type, proto, flags):
socket.gaierror: [Errno 11001] getaddrinfo failed

During handling of the above exception, another exception occurred:

Traceback (most recent call last):
  File "C:\Users\gizem\anaconda3\envs\soccer2\lib\site-packages\urllib3\connectionpool.py", line 703, in urlopen
    httplib_response = self._make_request(
  File "C:\Users\gizem\anaconda3\envs\soccer2\lib\site-packages\urllib3\connectionpool.py", line 386, in _make_request
    self._validate_conn(conn)
  File "C:\Users\gizem\anaconda3\envs\soccer2\lib\site-packages\urllib3\connectionpool.py", line 1040, in _validate_conn
    conn.connect()
  File "C:\Users\gizem\anaconda3\envs\soccer2\lib\site-packages\urllib3\connection.py", line 358, in connect
    self.sock = conn = self._new_conn()
  File "C:\Users\gizem\anaconda3\envs\soccer2\lib\site-packages\urllib3\connection.py", line 186, in _new_conn
    raise NewConnectionError(
urllib3.exceptions.NewConnectionError: <urllib3.connection.HTTPSConnection object at 0x00000159EBCBEB30>: Failed to establish a new connection: [Errno 11001] getaddrinfo failed

During handling of the above exception, another exception occurred:

Traceback (most recent call last):
  File "C:\Users\gizem\anaconda3\envs\soccer2\lib\site-packages\requests\adapters.py", line 440, in send
    resp = conn.urlopen(
  File "C:\Users\gizem\anaconda3\envs\soccer2\lib\site-packages\urllib3\connectionpool.py", line 785, in urlopen
    retries = retries.increment(
  File "C:\Users\gizem\anaconda3\envs\soccer2\lib\site-packages\urllib3\util\retry.py", line 592, in increment
    raise MaxRetryError(_pool, url, error or ResponseError(cause))
urllib3.exceptions.MaxRetryError: HTTPSConnectionPool(host='api.wandb.ai', port=443): Max retries exceeded with url: /graphql (Caused by NewConnectionError('<urllib3.connection.HTTPSConnection object at 0x00000159EBCBEB30>: Failed to establish a new connection: [Errno 11001] getaddrinfo failed'))

During handling of the above exception, another exception occurred:

Traceback (most recent call last):
  File "C:\Users\gizem\anaconda3\envs\soccer2\lib\site-packages\wandb\sdk\lib\retry.py", line 102, in __call__
    result = self._call_fn(*args, **kwargs)
  File "C:\Users\gizem\anaconda3\envs\soccer2\lib\site-packages\wandb\sdk\internal\internal_api.py", line 141, in execute
    return self.client.execute(*args, **kwargs)
  File "C:\Users\gizem\anaconda3\envs\soccer2\lib\site-packages\wandb\vendor\gql-0.2.0\wandb_gql\client.py", line 52, in execute
    result = self._get_result(document, *args, **kwargs)
  File "C:\Users\gizem\anaconda3\envs\soccer2\lib\site-packages\wandb\vendor\gql-0.2.0\wandb_gql\client.py", line 60, in _get_result
    return self.transport.execute(document, *args, **kwargs)
  File "C:\Users\gizem\anaconda3\envs\soccer2\lib\site-packages\wandb\vendor\gql-0.2.0\wandb_gql\transport\requests.py", line 38, in execute
    request = requests.post(self.url, **post_args)
  File "C:\Users\gizem\anaconda3\envs\soccer2\lib\site-packages\requests\api.py", line 117, in post
    return request('post', url, data=data, json=json, **kwargs)
  File "C:\Users\gizem\anaconda3\envs\soccer2\lib\site-packages\requests\api.py", line 61, in request
    return session.request(method=method, url=url, **kwargs)
  File "C:\Users\gizem\anaconda3\envs\soccer2\lib\site-packages\requests\sessions.py", line 529, in request
    resp = self.send(prep, **send_kwargs)
  File "C:\Users\gizem\anaconda3\envs\soccer2\lib\site-packages\requests\sessions.py", line 645, in send
    r = adapter.send(request, **kwargs)
  File "C:\Users\gizem\anaconda3\envs\soccer2\lib\site-packages\requests\adapters.py", line 519, in send
    raise ConnectionError(e, request=request)
requests.exceptions.ConnectionError: HTTPSConnectionPool(host='api.wandb.ai', port=443): Max retries exceeded with url: /graphql (Caused by NewConnectionError('<urllib3.connection.HTTPSConnection object at 0x00000159EBCBEB30>: Failed to establish a new connection: [Errno 11001] getaddrinfo failed'))
2022-05-27 16:03:51,904 WARNING FileStreamThread:16956 [file_stream.py:request_with_retry():594] requests_with_retry encountered retryable exception: HTTPSConnectionPool(host='api.wandb.ai', port=443): Max retries exceeded with url: /files/sml-eth/noisy-fair/2f8cby72/file_stream (Caused by NewConnectionError('<urllib3.connection.HTTPSConnection object at 0x00000159EBAF2860>: Failed to establish a new connection: [Errno 11001] getaddrinfo failed')). func: <bound method Session.post of <requests.sessions.Session object at 0x00000159EBA56170>>, args: ('https://api.wandb.ai/files/sml-eth/noisy-fair/2f8cby72/file_stream',), kwargs: {'json': {'files': {'wandb-events.jsonl': {'offset': 1, 'content': ['{"system.gpu.0.gpu": 0.0, "system.gpu.0.memory": 0.0, "system.gpu.0.memoryAllocated": 3.22, "system.gpu.0.temp": 49.0, "system.cpu": 25.51, "system.memory": 81.24, "system.disk": 84.7, "system.proc.memory.availableMB": 3043.74, "system.proc.memory.rssMB": 96.29, "system.proc.memory.percent": 0.59, "system.proc.cpu.threads": 16.2, "system.network.sent": 82109, "system.network.recv": 338502, "_wandb": true, "_timestamp": 1653656536, "_runtime": 81}']}}, 'dropped': 0}}
2022-05-27 16:03:57,948 INFO    Thread-11 :16956 [dir_watcher.py:_on_file_modified():230] file/dir modified: C:\Users\gizem\Documents\GitHub\noisy_fair\wandb\run-20220527_150054-2f8cby72\files\output.log
2022-05-27 16:04:01,436 WARNING FileStreamThread:16956 [file_stream.py:request_with_retry():594] requests_with_retry encountered retryable exception: HTTPSConnectionPool(host='api.wandb.ai', port=443): Max retries exceeded with url: /files/sml-eth/noisy-fair/2f8cby72/file_stream (Caused by NewConnectionError('<urllib3.connection.HTTPSConnection object at 0x00000159EBAF22C0>: Failed to establish a new connection: [Errno 11001] getaddrinfo failed')). func: <bound method Session.post of <requests.sessions.Session object at 0x00000159EBA56170>>, args: ('https://api.wandb.ai/files/sml-eth/noisy-fair/2f8cby72/file_stream',), kwargs: {'json': {'files': {'wandb-events.jsonl': {'offset': 1, 'content': ['{"system.gpu.0.gpu": 0.0, "system.gpu.0.memory": 0.0, "system.gpu.0.memoryAllocated": 3.22, "system.gpu.0.temp": 49.0, "system.cpu": 25.51, "system.memory": 81.24, "system.disk": 84.7, "system.proc.memory.availableMB": 3043.74, "system.proc.memory.rssMB": 96.29, "system.proc.memory.percent": 0.59, "system.proc.cpu.threads": 16.2, "system.network.sent": 82109, "system.network.recv": 338502, "_wandb": true, "_timestamp": 1653656536, "_runtime": 81}']}}, 'dropped': 0}}
2022-05-27 16:04:02,781 DEBUG   HandlerThread:16956 [handler.py:handle_request():141] handle_request: stop_status
2022-05-27 16:04:22,760 DEBUG   HandlerThread:16956 [handler.py:handle_request():141] handle_request: stop_status
2022-05-27 16:04:23,850 DEBUG   SenderThread:16956 [sender.py:send_request():249] send_request: stop_status
2022-05-27 16:04:24,908 DEBUG   SenderThread:16956 [sender.py:send_request():249] send_request: stop_status
2022-05-27 16:04:26,407 WARNING MainThread:16956 [internal.py:wandb_internal():155] Internal process interrupt: 1
2022-05-27 16:04:27,775 WARNING MainThread:16956 [internal.py:wandb_internal():155] Internal process interrupt: 2
2022-05-27 16:04:27,775 ERROR   MainThread:16956 [internal.py:wandb_internal():158] Internal process interrupted.
2022-05-27 16:04:27,808 INFO    HandlerThread:16956 [handler.py:finish():790] shutting down handler
2022-05-27 16:04:28,006 INFO    WriterThread:16956 [datastore.py:close():281] close: C:\Users\gizem\Documents\GitHub\noisy_fair\wandb\run-20220527_150054-2f8cby72\run-2f8cby72.wandb
2022-05-27 16:04:28,709 INFO    SenderThread:16956 [sender.py:finish():1107] shutting down sender
2022-05-27 16:04:28,710 INFO    SenderThread:16956 [dir_watcher.py:finish():283] shutting down directory watcher
2022-05-27 16:04:29,125 INFO    SenderThread:16956 [dir_watcher.py:finish():313] scan: C:\Users\gizem\Documents\GitHub\noisy_fair\wandb\run-20220527_150054-2f8cby72\files
2022-05-27 16:04:29,126 INFO    SenderThread:16956 [dir_watcher.py:finish():327] scan save: C:\Users\gizem\Documents\GitHub\noisy_fair\wandb\run-20220527_150054-2f8cby72\files\conda-environment.yaml conda-environment.yaml
2022-05-27 16:04:29,128 INFO    SenderThread:16956 [dir_watcher.py:finish():327] scan save: C:\Users\gizem\Documents\GitHub\noisy_fair\wandb\run-20220527_150054-2f8cby72\files\config.yaml config.yaml
2022-05-27 16:04:29,129 INFO    SenderThread:16956 [dir_watcher.py:finish():327] scan save: C:\Users\gizem\Documents\GitHub\noisy_fair\wandb\run-20220527_150054-2f8cby72\files\output.log output.log
2022-05-27 16:04:29,131 INFO    SenderThread:16956 [dir_watcher.py:finish():327] scan save: C:\Users\gizem\Documents\GitHub\noisy_fair\wandb\run-20220527_150054-2f8cby72\files\requirements.txt requirements.txt
2022-05-27 16:04:29,146 INFO    SenderThread:16956 [dir_watcher.py:finish():327] scan save: C:\Users\gizem\Documents\GitHub\noisy_fair\wandb\run-20220527_150054-2f8cby72\files\wandb-metadata.json wandb-metadata.json
2022-05-27 16:04:29,147 INFO    SenderThread:16956 [dir_watcher.py:finish():327] scan save: C:\Users\gizem\Documents\GitHub\noisy_fair\wandb\run-20220527_150054-2f8cby72\files\wandb-summary.json wandb-summary.json
2022-05-27 16:04:29,161 INFO    SenderThread:16956 [file_pusher.py:finish():145] shutting down file pusher
2022-05-27 16:04:29,162 INFO    SenderThread:16956 [file_pusher.py:join():150] waiting for file pusher
2022-05-27 16:04:32,499 INFO    Thread-20 :16956 [upload_job.py:push():137] Uploaded file C:\Users\gizem\Documents\GitHub\noisy_fair\wandb\run-20220527_150054-2f8cby72\files\requirements.txt
2022-05-27 16:04:32,499 INFO    Thread-19 :16956 [upload_job.py:push():137] Uploaded file C:\Users\gizem\Documents\GitHub\noisy_fair\wandb\run-20220527_150054-2f8cby72\files\output.log
2022-05-27 16:04:32,527 INFO    Thread-21 :16956 [upload_job.py:push():137] Uploaded file C:\Users\gizem\Documents\GitHub\noisy_fair\wandb\run-20220527_150054-2f8cby72\files\wandb-summary.json
2022-05-27 16:04:36,426 INFO    Thread-18 :16956 [upload_job.py:push():137] Uploaded file C:\Users\gizem\Documents\GitHub\noisy_fair\wandb\run-20220527_150054-2f8cby72\files\config.yaml
2022-05-27 16:04:36,985 INFO    MainThread:16956 [internal.py:handle_exit():82] Internal process exited
