2022-06-10 17:15:16 INFO Running runs: []
2022-06-10 17:15:17 INFO Agent received command: run
2022-06-10 17:15:17 INFO Agent starting run with config:
	architecture: ResNet
	epochs: 200
	learning_rate: 0.01
	loss_type: poly-sum
	momentum: 0
	n: 1024
	weight_decay: 0.01
2022-06-10 17:15:17 INFO About to run command: python train_multi.py --architecture=ResNet --epochs=200 --learning_rate=0.01 --loss_type=poly-sum --momentum=0 --n=1024 --weight_decay=0.01
2022-06-10 17:15:22 INFO Running runs: ['3li6h8y2']
2022-06-10 18:33:43 INFO Cleaning up finished run: 3li6h8y2
2022-06-10 18:33:44 INFO Agent received command: run
2022-06-10 18:33:44 INFO Agent starting run with config:
	architecture: ResNet
	epochs: 200
	learning_rate: 0.001
	loss_type: poly-sum
	momentum: 0.9
	n: 1024
	weight_decay: 0.001
2022-06-10 18:33:44 INFO About to run command: python train_multi.py --architecture=ResNet --epochs=200 --learning_rate=0.001 --loss_type=poly-sum --momentum=0.9 --n=1024 --weight_decay=0.001
2022-06-10 18:33:49 INFO Running runs: ['a50zo3w9']
2022-06-10 19:47:15 ERROR Retry attempt failed:
Traceback (most recent call last):
  File "c:\users\gizem\anaconda3\envs\soccer2\lib\site-packages\urllib3\connection.py", line 174, in _new_conn
    conn = connection.create_connection(
  File "c:\users\gizem\anaconda3\envs\soccer2\lib\site-packages\urllib3\util\connection.py", line 72, in create_connection
    for res in socket.getaddrinfo(host, port, family, socket.SOCK_STREAM):
  File "c:\users\gizem\anaconda3\envs\soccer2\lib\socket.py", line 955, in getaddrinfo
    for res in _socket.getaddrinfo(host, port, family, type, proto, flags):
socket.gaierror: [Errno 11001] getaddrinfo failed

During handling of the above exception, another exception occurred:

Traceback (most recent call last):
  File "c:\users\gizem\anaconda3\envs\soccer2\lib\site-packages\urllib3\connectionpool.py", line 703, in urlopen
    httplib_response = self._make_request(
  File "c:\users\gizem\anaconda3\envs\soccer2\lib\site-packages\urllib3\connectionpool.py", line 386, in _make_request
    self._validate_conn(conn)
  File "c:\users\gizem\anaconda3\envs\soccer2\lib\site-packages\urllib3\connectionpool.py", line 1040, in _validate_conn
    conn.connect()
  File "c:\users\gizem\anaconda3\envs\soccer2\lib\site-packages\urllib3\connection.py", line 358, in connect
    self.sock = conn = self._new_conn()
  File "c:\users\gizem\anaconda3\envs\soccer2\lib\site-packages\urllib3\connection.py", line 186, in _new_conn
    raise NewConnectionError(
urllib3.exceptions.NewConnectionError: <urllib3.connection.HTTPSConnection object at 0x0000018AAC676500>: Failed to establish a new connection: [Errno 11001] getaddrinfo failed

During handling of the above exception, another exception occurred:

Traceback (most recent call last):
  File "c:\users\gizem\anaconda3\envs\soccer2\lib\site-packages\requests\adapters.py", line 440, in send
    resp = conn.urlopen(
  File "c:\users\gizem\anaconda3\envs\soccer2\lib\site-packages\urllib3\connectionpool.py", line 785, in urlopen
    retries = retries.increment(
  File "c:\users\gizem\anaconda3\envs\soccer2\lib\site-packages\urllib3\util\retry.py", line 592, in increment
    raise MaxRetryError(_pool, url, error or ResponseError(cause))
urllib3.exceptions.MaxRetryError: HTTPSConnectionPool(host='api.wandb.ai', port=443): Max retries exceeded with url: /graphql (Caused by NewConnectionError('<urllib3.connection.HTTPSConnection object at 0x0000018AAC676500>: Failed to establish a new connection: [Errno 11001] getaddrinfo failed'))

During handling of the above exception, another exception occurred:

Traceback (most recent call last):
  File "c:\users\gizem\anaconda3\envs\soccer2\lib\site-packages\wandb\sdk\lib\retry.py", line 102, in __call__
    result = self._call_fn(*args, **kwargs)
  File "c:\users\gizem\anaconda3\envs\soccer2\lib\site-packages\wandb\sdk\internal\internal_api.py", line 140, in execute
    return self.client.execute(*args, **kwargs)
  File "c:\users\gizem\anaconda3\envs\soccer2\lib\site-packages\wandb\vendor\gql-0.2.0\wandb_gql\client.py", line 52, in execute
    result = self._get_result(document, *args, **kwargs)
  File "c:\users\gizem\anaconda3\envs\soccer2\lib\site-packages\wandb\vendor\gql-0.2.0\wandb_gql\client.py", line 60, in _get_result
    return self.transport.execute(document, *args, **kwargs)
  File "c:\users\gizem\anaconda3\envs\soccer2\lib\site-packages\wandb\vendor\gql-0.2.0\wandb_gql\transport\requests.py", line 38, in execute
    request = requests.post(self.url, **post_args)
  File "c:\users\gizem\anaconda3\envs\soccer2\lib\site-packages\requests\api.py", line 117, in post
    return request('post', url, data=data, json=json, **kwargs)
  File "c:\users\gizem\anaconda3\envs\soccer2\lib\site-packages\requests\api.py", line 61, in request
    return session.request(method=method, url=url, **kwargs)
  File "c:\users\gizem\anaconda3\envs\soccer2\lib\site-packages\requests\sessions.py", line 529, in request
    resp = self.send(prep, **send_kwargs)
  File "c:\users\gizem\anaconda3\envs\soccer2\lib\site-packages\requests\sessions.py", line 645, in send
    r = adapter.send(request, **kwargs)
  File "c:\users\gizem\anaconda3\envs\soccer2\lib\site-packages\requests\adapters.py", line 519, in send
    raise ConnectionError(e, request=request)
requests.exceptions.ConnectionError: HTTPSConnectionPool(host='api.wandb.ai', port=443): Max retries exceeded with url: /graphql (Caused by NewConnectionError('<urllib3.connection.HTTPSConnection object at 0x0000018AAC676500>: Failed to establish a new connection: [Errno 11001] getaddrinfo failed'))
