2022-05-04 11:48:51,683 INFO    MainThread:27228 [internal.py:wandb_internal():92] W&B internal server running at pid: 27228, started at: 2022-05-04 11:48:51.683125
2022-05-04 11:48:51,686 INFO    WriterThread:27228 [datastore.py:open_for_write():77] open: C:\Users\gizem\Documents\GitHub\noisy_fair\wandb\run-20220504_114849-fcylzcx8\run-fcylzcx8.wandb
2022-05-04 11:48:51,690 DEBUG   SenderThread:27228 [sender.py:send():235] send: header
2022-05-04 11:48:51,690 DEBUG   SenderThread:27228 [sender.py:send():235] send: run
2022-05-04 11:49:19,822 DEBUG   HandlerThread:27228 [handler.py:handle_request():141] handle_request: shutdown
2022-05-04 11:49:19,842 INFO    HandlerThread:27228 [handler.py:finish():790] shutting down handler
2022-05-04 11:49:19,910 INFO    WriterThread:27228 [datastore.py:close():281] close: C:\Users\gizem\Documents\GitHub\noisy_fair\wandb\run-20220504_114849-fcylzcx8\run-fcylzcx8.wandb
2022-05-04 11:49:31,049 ERROR   SenderThread:27228 [retry.py:__call__():126] Retry attempt failed:
Traceback (most recent call last):
  File "C:\Users\gizem\anaconda3\envs\iw\lib\site-packages\urllib3\connectionpool.py", line 703, in urlopen
    httplib_response = self._make_request(
  File "C:\Users\gizem\anaconda3\envs\iw\lib\site-packages\urllib3\connectionpool.py", line 449, in _make_request
    six.raise_from(e, None)
  File "<string>", line 3, in raise_from
  File "C:\Users\gizem\anaconda3\envs\iw\lib\site-packages\urllib3\connectionpool.py", line 444, in _make_request
    httplib_response = conn.getresponse()
  File "C:\Users\gizem\anaconda3\envs\iw\lib\http\client.py", line 1374, in getresponse
    response.begin()
  File "C:\Users\gizem\anaconda3\envs\iw\lib\http\client.py", line 318, in begin
    version, status, reason = self._read_status()
  File "C:\Users\gizem\anaconda3\envs\iw\lib\http\client.py", line 287, in _read_status
    raise RemoteDisconnected("Remote end closed connection without"
http.client.RemoteDisconnected: Remote end closed connection without response

During handling of the above exception, another exception occurred:

Traceback (most recent call last):
  File "C:\Users\gizem\anaconda3\envs\iw\lib\site-packages\requests\adapters.py", line 440, in send
    resp = conn.urlopen(
  File "C:\Users\gizem\anaconda3\envs\iw\lib\site-packages\urllib3\connectionpool.py", line 785, in urlopen
    retries = retries.increment(
  File "C:\Users\gizem\anaconda3\envs\iw\lib\site-packages\urllib3\util\retry.py", line 550, in increment
    raise six.reraise(type(error), error, _stacktrace)
  File "C:\Users\gizem\anaconda3\envs\iw\lib\site-packages\urllib3\packages\six.py", line 769, in reraise
    raise value.with_traceback(tb)
  File "C:\Users\gizem\anaconda3\envs\iw\lib\site-packages\urllib3\connectionpool.py", line 703, in urlopen
    httplib_response = self._make_request(
  File "C:\Users\gizem\anaconda3\envs\iw\lib\site-packages\urllib3\connectionpool.py", line 449, in _make_request
    six.raise_from(e, None)
  File "<string>", line 3, in raise_from
  File "C:\Users\gizem\anaconda3\envs\iw\lib\site-packages\urllib3\connectionpool.py", line 444, in _make_request
    httplib_response = conn.getresponse()
  File "C:\Users\gizem\anaconda3\envs\iw\lib\http\client.py", line 1374, in getresponse
    response.begin()
  File "C:\Users\gizem\anaconda3\envs\iw\lib\http\client.py", line 318, in begin
    version, status, reason = self._read_status()
  File "C:\Users\gizem\anaconda3\envs\iw\lib\http\client.py", line 287, in _read_status
    raise RemoteDisconnected("Remote end closed connection without"
urllib3.exceptions.ProtocolError: ('Connection aborted.', RemoteDisconnected('Remote end closed connection without response'))

During handling of the above exception, another exception occurred:

Traceback (most recent call last):
  File "C:\Users\gizem\anaconda3\envs\iw\lib\site-packages\wandb\sdk\lib\retry.py", line 102, in __call__
    result = self._call_fn(*args, **kwargs)
  File "C:\Users\gizem\anaconda3\envs\iw\lib\site-packages\wandb\sdk\internal\internal_api.py", line 141, in execute
    return self.client.execute(*args, **kwargs)
  File "C:\Users\gizem\anaconda3\envs\iw\lib\site-packages\wandb\vendor\gql-0.2.0\wandb_gql\client.py", line 52, in execute
    result = self._get_result(document, *args, **kwargs)
  File "C:\Users\gizem\anaconda3\envs\iw\lib\site-packages\wandb\vendor\gql-0.2.0\wandb_gql\client.py", line 60, in _get_result
    return self.transport.execute(document, *args, **kwargs)
  File "C:\Users\gizem\anaconda3\envs\iw\lib\site-packages\wandb\vendor\gql-0.2.0\wandb_gql\transport\requests.py", line 38, in execute
    request = requests.post(self.url, **post_args)
  File "C:\Users\gizem\anaconda3\envs\iw\lib\site-packages\requests\api.py", line 117, in post
    return request('post', url, data=data, json=json, **kwargs)
  File "C:\Users\gizem\anaconda3\envs\iw\lib\site-packages\requests\api.py", line 61, in request
    return session.request(method=method, url=url, **kwargs)
  File "C:\Users\gizem\anaconda3\envs\iw\lib\site-packages\requests\sessions.py", line 529, in request
    resp = self.send(prep, **send_kwargs)
  File "C:\Users\gizem\anaconda3\envs\iw\lib\site-packages\requests\sessions.py", line 645, in send
    r = adapter.send(request, **kwargs)
  File "C:\Users\gizem\anaconda3\envs\iw\lib\site-packages\requests\adapters.py", line 501, in send
    raise ConnectionError(err, request=request)
requests.exceptions.ConnectionError: ('Connection aborted.', RemoteDisconnected('Remote end closed connection without response'))
2022-05-04 11:51:12,711 INFO    SenderThread:27228 [dir_watcher.py:__init__():169] watching files in: C:\Users\gizem\Documents\GitHub\noisy_fair\wandb\run-20220504_114849-fcylzcx8\files
2022-05-04 11:51:12,713 INFO    SenderThread:27228 [sender.py:_start_run_threads():812] run started: fcylzcx8 with start time 1651657729
2022-05-04 11:51:12,714 INFO    SenderThread:27228 [sender.py:finish():1107] shutting down sender
2022-05-04 11:51:12,715 INFO    SenderThread:27228 [dir_watcher.py:finish():283] shutting down directory watcher
2022-05-04 11:51:13,720 INFO    SenderThread:27228 [dir_watcher.py:finish():313] scan: C:\Users\gizem\Documents\GitHub\noisy_fair\wandb\run-20220504_114849-fcylzcx8\files
2022-05-04 11:51:13,722 INFO    SenderThread:27228 [dir_watcher.py:finish():327] scan save: C:\Users\gizem\Documents\GitHub\noisy_fair\wandb\run-20220504_114849-fcylzcx8\files\config.yaml config.yaml
2022-05-04 11:51:13,724 INFO    SenderThread:27228 [file_pusher.py:finish():145] shutting down file pusher
2022-05-04 11:51:13,725 INFO    SenderThread:27228 [file_pusher.py:join():150] waiting for file pusher
2022-05-04 11:51:16,505 INFO    Thread-13 :27228 [upload_job.py:push():137] Uploaded file C:\Users\gizem\Documents\GitHub\noisy_fair\wandb\run-20220504_114849-fcylzcx8\files\config.yaml
2022-05-04 11:51:18,203 INFO    MainThread:27228 [internal.py:handle_exit():82] Internal process exited
