2022-05-04 11:48:49,444 INFO    MainThread:27688 [wandb_setup.py:_flush():75] Loading settings from C:\Users\gizem\.config\wandb\settings
2022-05-04 11:48:49,444 INFO    MainThread:27688 [wandb_setup.py:_flush():75] Loading settings from C:\Users\gizem\Documents\GitHub\noisy_fair\wandb\settings
2022-05-04 11:48:49,444 INFO    MainThread:27688 [wandb_setup.py:_flush():75] Loading settings from environment variables: {}
2022-05-04 11:48:49,444 INFO    MainThread:27688 [wandb_setup.py:_flush():75] Inferring run settings from compute environment: {'program_relpath': 'margin_interp.py', 'program': 'c:\\Users\\gizem\\Documents\\GitHub\\noisy_fair\\margin_interp.py'}
2022-05-04 11:48:49,445 INFO    MainThread:27688 [wandb_init.py:_log_setup():438] Logging user logs to C:\Users\gizem\Documents\GitHub\noisy_fair\wandb\run-20220504_114849-fcylzcx8\logs\debug.log
2022-05-04 11:48:49,461 INFO    MainThread:27688 [wandb_init.py:_log_setup():439] Logging internal logs to C:\Users\gizem\Documents\GitHub\noisy_fair\wandb\run-20220504_114849-fcylzcx8\logs\debug-internal.log
2022-05-04 11:48:49,463 INFO    MainThread:27688 [wandb_init.py:init():472] calling init triggers
2022-05-04 11:48:49,464 INFO    MainThread:27688 [wandb_init.py:init():475] wandb.init called with sweep_config: {}
config: {'n_train': 10, 'n_test': 10000.0, 'n_features': 50, 'tau': 1.0, 'SNR': 10, 'n_informative': 50, 'n_redundant': 0, 'n_repeated': 0, 'n_useless': 0, 'n_clusters_per_class': 1, 'class_sep': 3.1622776601683795, 's': 1, 'label_noise_prob': 0}
2022-05-04 11:48:49,465 INFO    MainThread:27688 [wandb_init.py:init():525] starting backend
2022-05-04 11:48:49,465 INFO    MainThread:27688 [backend.py:_multiprocessing_setup():99] multiprocessing start_methods=spawn, using: spawn
2022-05-04 11:48:49,480 INFO    MainThread:27688 [backend.py:ensure_launched():219] starting backend process...
2022-05-04 11:48:49,675 INFO    MainThread:27688 [backend.py:ensure_launched():224] started backend process with pid: 27228
2022-05-04 11:48:49,675 INFO    MainThread:27688 [wandb_init.py:init():534] backend started and connected
2022-05-04 11:48:49,717 INFO    MainThread:27688 [wandb_init.py:init():598] updated telemetry
2022-05-04 11:48:49,803 INFO    MainThread:27688 [wandb_init.py:init():629] communicating run to backend with 30 second timeout
2022-05-04 11:49:19,817 INFO    MainThread:27688 [interface_shared.py:_communicate_run():325] couldn't get run from backend
2022-05-04 11:49:19,818 ERROR   MainThread:27688 [wandb_init.py:init():634] backend process timed out
2022-05-04 11:49:19,818 ERROR   MainThread:27688 [wandb_init.py:init():645] encountered error: Error communicating with wandb process
try: wandb.init(settings=wandb.Settings(start_method='fork'))
or:  wandb.init(settings=wandb.Settings(start_method='thread'))
For more info see: https://docs.wandb.ai/library/init#init-start-error
2022-05-04 11:50:06,828 ERROR   Thread-7 (wrapped_target):27688 [retry.py:__call__():126] Retry attempt failed:
Traceback (most recent call last):
  File "C:\Users\gizem\anaconda3\envs\iw\lib\site-packages\urllib3\connection.py", line 174, in _new_conn
    conn = connection.create_connection(
  File "C:\Users\gizem\anaconda3\envs\iw\lib\site-packages\urllib3\util\connection.py", line 95, in create_connection
    raise err
  File "C:\Users\gizem\anaconda3\envs\iw\lib\site-packages\urllib3\util\connection.py", line 85, in create_connection
    sock.connect(sa)
TimeoutError: timed out

During handling of the above exception, another exception occurred:

Traceback (most recent call last):
  File "C:\Users\gizem\anaconda3\envs\iw\lib\site-packages\urllib3\connectionpool.py", line 703, in urlopen
    httplib_response = self._make_request(
  File "C:\Users\gizem\anaconda3\envs\iw\lib\site-packages\urllib3\connectionpool.py", line 386, in _make_request
    self._validate_conn(conn)
  File "C:\Users\gizem\anaconda3\envs\iw\lib\site-packages\urllib3\connectionpool.py", line 1040, in _validate_conn
    conn.connect()
  File "C:\Users\gizem\anaconda3\envs\iw\lib\site-packages\urllib3\connection.py", line 358, in connect
    self.sock = conn = self._new_conn()
  File "C:\Users\gizem\anaconda3\envs\iw\lib\site-packages\urllib3\connection.py", line 179, in _new_conn
    raise ConnectTimeoutError(
urllib3.exceptions.ConnectTimeoutError: (<urllib3.connection.HTTPSConnection object at 0x0000020B0F259F30>, 'Connection to api.wandb.ai timed out. (connect timeout=10)')

During handling of the above exception, another exception occurred:

Traceback (most recent call last):
  File "C:\Users\gizem\anaconda3\envs\iw\lib\site-packages\requests\adapters.py", line 440, in send
    resp = conn.urlopen(
  File "C:\Users\gizem\anaconda3\envs\iw\lib\site-packages\urllib3\connectionpool.py", line 785, in urlopen
    retries = retries.increment(
  File "C:\Users\gizem\anaconda3\envs\iw\lib\site-packages\urllib3\util\retry.py", line 592, in increment
    raise MaxRetryError(_pool, url, error or ResponseError(cause))
urllib3.exceptions.MaxRetryError: HTTPSConnectionPool(host='api.wandb.ai', port=443): Max retries exceeded with url: /graphql (Caused by ConnectTimeoutError(<urllib3.connection.HTTPSConnection object at 0x0000020B0F259F30>, 'Connection to api.wandb.ai timed out. (connect timeout=10)'))

During handling of the above exception, another exception occurred:

Traceback (most recent call last):
  File "C:\Users\gizem\anaconda3\envs\iw\lib\site-packages\wandb\sdk\lib\retry.py", line 102, in __call__
    result = self._call_fn(*args, **kwargs)
  File "C:\Users\gizem\anaconda3\envs\iw\lib\site-packages\wandb\sdk\internal\internal_api.py", line 141, in execute
    return self.client.execute(*args, **kwargs)
  File "C:\Users\gizem\anaconda3\envs\iw\lib\site-packages\wandb\vendor\gql-0.2.0\wandb_gql\client.py", line 52, in execute
    result = self._get_result(document, *args, **kwargs)
  File "C:\Users\gizem\anaconda3\envs\iw\lib\site-packages\wandb\vendor\gql-0.2.0\wandb_gql\client.py", line 60, in _get_result
    return self.transport.execute(document, *args, **kwargs)
  File "C:\Users\gizem\anaconda3\envs\iw\lib\site-packages\wandb\vendor\gql-0.2.0\wandb_gql\transport\requests.py", line 38, in execute
    request = requests.post(self.url, **post_args)
  File "C:\Users\gizem\anaconda3\envs\iw\lib\site-packages\requests\api.py", line 117, in post
    return request('post', url, data=data, json=json, **kwargs)
  File "C:\Users\gizem\anaconda3\envs\iw\lib\site-packages\requests\api.py", line 61, in request
    return session.request(method=method, url=url, **kwargs)
  File "C:\Users\gizem\anaconda3\envs\iw\lib\site-packages\requests\sessions.py", line 529, in request
    resp = self.send(prep, **send_kwargs)
  File "C:\Users\gizem\anaconda3\envs\iw\lib\site-packages\requests\sessions.py", line 645, in send
    r = adapter.send(request, **kwargs)
  File "C:\Users\gizem\anaconda3\envs\iw\lib\site-packages\requests\adapters.py", line 507, in send
    raise ConnectTimeout(e, request=request)
requests.exceptions.ConnectTimeout: HTTPSConnectionPool(host='api.wandb.ai', port=443): Max retries exceeded with url: /graphql (Caused by ConnectTimeoutError(<urllib3.connection.HTTPSConnection object at 0x0000020B0F259F30>, 'Connection to api.wandb.ai timed out. (connect timeout=10)'))
2022-05-04 11:51:18,308 WARNING MainThread:27688 [wandb_init.py:init():1017] interrupted
Traceback (most recent call last):
  File "C:\Users\gizem\anaconda3\envs\iw\lib\site-packages\wandb\sdk\wandb_init.py", line 996, in init
    run = wi.init()
  File "C:\Users\gizem\anaconda3\envs\iw\lib\site-packages\wandb\sdk\wandb_init.py", line 649, in init
    backend.cleanup()
  File "C:\Users\gizem\anaconda3\envs\iw\lib\site-packages\wandb\sdk\backend\backend.py", line 250, in cleanup
    self.wandb_process.join()
  File "C:\Users\gizem\anaconda3\envs\iw\lib\multiprocessing\process.py", line 149, in join
    res = self._popen.wait(timeout)
  File "C:\Users\gizem\anaconda3\envs\iw\lib\multiprocessing\popen_spawn_win32.py", line 108, in wait
    res = _winapi.WaitForSingleObject(int(self._handle), msecs)
KeyboardInterrupt
