2022-04-28 11:56:41,630 INFO    MainThread:27348 [internal.py:wandb_internal():92] W&B internal server running at pid: 27348, started at: 2022-04-28 11:56:41.628953
2022-04-28 11:56:41,635 INFO    WriterThread:27348 [datastore.py:open_for_write():77] open: C:\Users\gizem\Documents\GitHub\noisy_fair\wandb\run-20220428_115638-29oxcun7\run-29oxcun7.wandb
2022-04-28 11:56:41,645 DEBUG   SenderThread:27348 [sender.py:send():235] send: header
2022-04-28 11:56:41,645 DEBUG   SenderThread:27348 [sender.py:send():235] send: run
2022-04-28 11:56:45,219 ERROR   SenderThread:27348 [retry.py:__call__():126] Retry attempt failed:
Traceback (most recent call last):
  File "C:\Users\gizem\anaconda3\envs\iw\lib\site-packages\urllib3\connection.py", line 174, in _new_conn
    conn = connection.create_connection(
  File "C:\Users\gizem\anaconda3\envs\iw\lib\site-packages\urllib3\util\connection.py", line 72, in create_connection
    for res in socket.getaddrinfo(host, port, family, socket.SOCK_STREAM):
  File "C:\Users\gizem\anaconda3\envs\iw\lib\socket.py", line 955, in getaddrinfo
    for res in _socket.getaddrinfo(host, port, family, type, proto, flags):
socket.gaierror: [Errno 11001] getaddrinfo failed

During handling of the above exception, another exception occurred:

Traceback (most recent call last):
  File "C:\Users\gizem\anaconda3\envs\iw\lib\site-packages\urllib3\connectionpool.py", line 703, in urlopen
    httplib_response = self._make_request(
  File "C:\Users\gizem\anaconda3\envs\iw\lib\site-packages\urllib3\connectionpool.py", line 386, in _make_request
    self._validate_conn(conn)
  File "C:\Users\gizem\anaconda3\envs\iw\lib\site-packages\urllib3\connectionpool.py", line 1040, in _validate_conn
    conn.connect()
  File "C:\Users\gizem\anaconda3\envs\iw\lib\site-packages\urllib3\connection.py", line 358, in connect
    self.sock = conn = self._new_conn()
  File "C:\Users\gizem\anaconda3\envs\iw\lib\site-packages\urllib3\connection.py", line 186, in _new_conn
    raise NewConnectionError(
urllib3.exceptions.NewConnectionError: <urllib3.connection.HTTPSConnection object at 0x000002515C921120>: Failed to establish a new connection: [Errno 11001] getaddrinfo failed

During handling of the above exception, another exception occurred:

Traceback (most recent call last):
  File "C:\Users\gizem\anaconda3\envs\iw\lib\site-packages\requests\adapters.py", line 440, in send
    resp = conn.urlopen(
  File "C:\Users\gizem\anaconda3\envs\iw\lib\site-packages\urllib3\connectionpool.py", line 785, in urlopen
    retries = retries.increment(
  File "C:\Users\gizem\anaconda3\envs\iw\lib\site-packages\urllib3\util\retry.py", line 592, in increment
    raise MaxRetryError(_pool, url, error or ResponseError(cause))
urllib3.exceptions.MaxRetryError: HTTPSConnectionPool(host='api.wandb.ai', port=443): Max retries exceeded with url: /graphql (Caused by NewConnectionError('<urllib3.connection.HTTPSConnection object at 0x000002515C921120>: Failed to establish a new connection: [Errno 11001] getaddrinfo failed'))

During handling of the above exception, another exception occurred:

Traceback (most recent call last):
  File "C:\Users\gizem\anaconda3\envs\iw\lib\site-packages\wandb\sdk\lib\retry.py", line 102, in __call__
    result = self._call_fn(*args, **kwargs)
  File "C:\Users\gizem\anaconda3\envs\iw\lib\site-packages\wandb\sdk\internal\internal_api.py", line 141, in execute
    return self.client.execute(*args, **kwargs)
  File "C:\Users\gizem\anaconda3\envs\iw\lib\site-packages\wandb\vendor\gql-0.2.0\wandb_gql\client.py", line 52, in execute
    result = self._get_result(document, *args, **kwargs)
  File "C:\Users\gizem\anaconda3\envs\iw\lib\site-packages\wandb\vendor\gql-0.2.0\wandb_gql\client.py", line 60, in _get_result
    return self.transport.execute(document, *args, **kwargs)
  File "C:\Users\gizem\anaconda3\envs\iw\lib\site-packages\wandb\vendor\gql-0.2.0\wandb_gql\transport\requests.py", line 38, in execute
    request = requests.post(self.url, **post_args)
  File "C:\Users\gizem\anaconda3\envs\iw\lib\site-packages\requests\api.py", line 117, in post
    return request('post', url, data=data, json=json, **kwargs)
  File "C:\Users\gizem\anaconda3\envs\iw\lib\site-packages\requests\api.py", line 61, in request
    return session.request(method=method, url=url, **kwargs)
  File "C:\Users\gizem\anaconda3\envs\iw\lib\site-packages\requests\sessions.py", line 529, in request
    resp = self.send(prep, **send_kwargs)
  File "C:\Users\gizem\anaconda3\envs\iw\lib\site-packages\requests\sessions.py", line 645, in send
    r = adapter.send(request, **kwargs)
  File "C:\Users\gizem\anaconda3\envs\iw\lib\site-packages\requests\adapters.py", line 519, in send
    raise ConnectionError(e, request=request)
requests.exceptions.ConnectionError: HTTPSConnectionPool(host='api.wandb.ai', port=443): Max retries exceeded with url: /graphql (Caused by NewConnectionError('<urllib3.connection.HTTPSConnection object at 0x000002515C921120>: Failed to establish a new connection: [Errno 11001] getaddrinfo failed'))
2022-04-28 11:57:09,290 DEBUG   HandlerThread:27348 [handler.py:handle_request():141] handle_request: shutdown
2022-04-28 11:57:09,295 INFO    HandlerThread:27348 [handler.py:finish():790] shutting down handler
2022-04-28 11:57:09,878 INFO    WriterThread:27348 [datastore.py:close():281] close: C:\Users\gizem\Documents\GitHub\noisy_fair\wandb\run-20220428_115638-29oxcun7\run-29oxcun7.wandb
2022-04-28 11:59:02,117 INFO    SenderThread:27348 [dir_watcher.py:__init__():169] watching files in: C:\Users\gizem\Documents\GitHub\noisy_fair\wandb\run-20220428_115638-29oxcun7\files
2022-04-28 11:59:02,119 INFO    SenderThread:27348 [sender.py:_start_run_threads():812] run started: 29oxcun7 with start time 1651139799
2022-04-28 11:59:02,119 INFO    SenderThread:27348 [sender.py:finish():1107] shutting down sender
2022-04-28 11:59:02,120 INFO    SenderThread:27348 [dir_watcher.py:finish():283] shutting down directory watcher
2022-04-28 11:59:03,123 INFO    SenderThread:27348 [dir_watcher.py:finish():313] scan: C:\Users\gizem\Documents\GitHub\noisy_fair\wandb\run-20220428_115638-29oxcun7\files
2022-04-28 11:59:03,124 INFO    SenderThread:27348 [dir_watcher.py:finish():327] scan save: C:\Users\gizem\Documents\GitHub\noisy_fair\wandb\run-20220428_115638-29oxcun7\files\config.yaml config.yaml
2022-04-28 11:59:03,125 INFO    SenderThread:27348 [file_pusher.py:finish():145] shutting down file pusher
2022-04-28 11:59:03,125 INFO    SenderThread:27348 [file_pusher.py:join():150] waiting for file pusher
2022-04-28 11:59:05,888 INFO    Thread-13 :27348 [upload_job.py:push():137] Uploaded file C:\Users\gizem\Documents\GitHub\noisy_fair\wandb\run-20220428_115638-29oxcun7\files\config.yaml
2022-04-28 11:59:07,632 INFO    MainThread:27348 [internal.py:handle_exit():82] Internal process exited
